package Exception;

public class Test12 {
public static void main(String...das)
{
	try{
		System.out.println("inside try:::");
	}
	catch(ArithmeticException e)
	{
		
	}
	catch(Exception obj)
	{
		
	}
}
}